<robot name="r2d2">
#a planar joint can move around in a plane, or two dimensions.
#a floating joint is unconstrained, and can move around in any of the three dimensions

 <material name="green">
	#first three value are red,green and green last 1= alpha channels(if it is 1 the it will be less visible) three values are [0,1]
	<color rgba="0 1 0 1"/>
 </material>
 <material name="black">
     <color rgba="0 0 0 1"/>
 </material>

 <material name="white">
	<color rgba="1 1 1 1"/>
 </material>
 <material name="red">
	<color rgba="1 0 0 1"/>
 </material>



#create cylinder 0.6 meters long with a 0.2 meter radius 
 <link name="base_link">
  <visual>
   <geometry>
    <cylinder length="0.6" radius="0.2"/>
   </geometry>
	<material name="green"/>
  </visual>
#there are two types Quicker processing and Safe Zone(it's prvent anything reache this zone user for sensative part like head)

   <collision>
         <geometry>
           <cylinder length="0.6" radius="0.2"/>
         </geometry>
    </collision>
#ata jorota prokas kore(mass is defined in kilograms)
#3x3 rotational inertia matrix is specified with the inertia element. 
#middle gulor addition hobe ixx/iyy/izz=1e-3 (maximum published weight 600kg)
#can define orgin to specify the center of gravity.
#also can define the the behavior when they are in contact with other metal
#("contact_coefficients=(type=mu or kp or kd))"; Joint Dynamics =(type=friction or damping)
    <inertial>
         <mass value="10"/>
         <inertia ixx="0.4" ixy="0.0" ixz="0.0" iyy="0.4" iyz="0.0" izz="0.2"/>
    </inertial>
  </link>




 <link name="right_leg">
   <visual>
    <geometry>
	#length=0.6 height 0.1 width 0.2(same orgin as the cylinder)
        <box size="0.6 0.1 0.2"/>
    </geometry>
	#it defines where the lege will be rpy=roll pitch yaw
	#offset the orgin down by -0.3 meter has bring the leg bellow
	# 1.57075 is the halfo of pi=3.1614 that is how we fix the leg alongside the main cylinder
         <origin rpy="0 1.57075 0" xyz="0 0 -0.3"/>
	 <material name="white"/>
   </visual>
 </link>

 

#important type of joints: continuous, revolute and prismatic. 
 <joint name="base_to_right_leg" type="fixed">
     <parent link="base_link"/>
     <child link="right_leg"/>
	#(roll pitch Yaw) is not defiend so chind frame have the default same orientation.
     <origin xyz="0 -0.22 0.25"/>
 </joint>

   <link name="right_base">
     <visual>
       <geometry>
         <box size="0.4 0.1 0.1"/>
       </geometry>
       <material name="white"/>
     </visual>
   </link>

   <joint name="right_base_joint" type="fixed">
      <parent link="right_leg"/>
       <child link="right_base"/>
       <origin xyz="0 0 -0.6"/>
   </joint>


 <link name="right_front_wheel">
       <visual>
         <origin rpy="1.57075 0 0" xyz="0 0 0"/>
         <geometry>
           <cylinder length="0.1" radius="0.035"/>
         </geometry>
         <material name="black"/>
         <origin rpy="0 0 0" xyz="0 0 0"/>
       </visual>
 </link>


 <joint name="right_front_wheel_joint" type="fixed">
       <parent link="right_base"/>
       <child link="right_front_wheel"/>
       <origin rpy="0 0 0" xyz="0.133333333333 0 -0.085"/>
 </joint>


   <link name="right_back_wheel">
       <visual>
         <origin rpy="1.57075 0 0" xyz="0 0 0"/>
         <geometry>
           <cylinder length="0.1" radius="0.035"/>
         </geometry>
         <material name="black"/>
       </visual>
     </link>
     <joint name="right_back_wheel_joint" type="fixed">
       <parent link="right_base"/>
       <child link="right_back_wheel"/>
       <origin rpy="0 0 0" xyz="-0.133333333333 0 -0.085"/>
     </joint>


  <link name="left_leg">
     <visual>
       <geometry>
         <box size="0.6 0.1 0.2"/>
       </geometry>
       <origin rpy="0 1.57075 0" xyz="0 0 -0.3"/>
       <material name="white"/>
     </visual>
   </link>
 
   <joint name="base_to_left_leg" type="fixed">
     <parent link="base_link"/>
     <child link="left_leg"/>
     <origin xyz="0 0.22 0.25"/>
   </joint>
   <link name="left_base">
      <visual>
        <geometry>
          <box size="0.4 0.1 0.1"/>
        </geometry>
        <material name="white"/>
      </visual>
    </link>
  
    <joint name="left_base_joint" type="fixed">
      <parent link="left_leg"/>
      <child link="left_base"/>
      <origin xyz="0 0 -0.6"/>
    </joint>
  
    <link name="left_front_wheel">
      <visual>
        <origin rpy="1.57075 0 0" xyz="0 0 0"/>
        <geometry>
          <cylinder length="0.1" radius="0.035"/>
        </geometry>
        <material name="black"/>
      </visual>
    </link>
    <joint name="left_front_wheel_joint" type="fixed">
      <parent link="left_base"/>
      <child link="left_front_wheel"/>
      <origin rpy="0 0 0" xyz="0.133333333333 0 -0.085"/>
    </joint>
  
    <link name="left_back_wheel">
      <visual>
        <origin rpy="1.57075 0 0" xyz="0 0 0"/>
        <geometry>
         <cylinder length="0.1" radius="0.035"/>
        </geometry>
        <material name="black"/>
      </visual>
    </link>
    <joint name="left_back_wheel_joint" type="fixed">
     <parent link="left_base"/>
      <child link="left_back_wheel"/>
      <origin rpy="0 0 0" xyz="-0.133333333333 0 -0.085"/>
    </joint>
#a prismatic joint moves along an axis
 <joint name="gripper_extension" type="prismatic">
      <parent link="base_link"/>
      <child link="gripper_pole"/>
	<limit effort="1000.0" lower="-0.38" upper="0" velocity="0.5"/>
      <origin rpy="0 0 0" xyz="0.19 0 0.2"/>
    </joint>
  
    <link name="gripper_pole">
      <visual>
        <geometry>
          <cylinder length="0.2" radius="0.01"/>
        </geometry>
        <origin rpy="0 1.57075 0 " xyz="0.1 0 0"/>
      </visual>
    </link>
#revolute joint rotate in the same way that the continuous joints do, but they have strict limits.upper and lower limits(radians unit)
    <joint name="left_gripper_joint" type="revolute">
 	<axis xyz="0 0 1"/>
        <limit effort="1000.0" lower="0.0" upper="0.548" velocity="0.5"/>
      <origin rpy="0 0 0" xyz="0.2 0.01 0"/>
      <parent link="gripper_pole"/>
      <child link="left_gripper"/>
    </joint>
  
    <link name="left_gripper">
      <visual>
        <origin rpy="0.0 0 0" xyz="0 0 0"/>
        <geometry>
         <mesh filename="package://urdf_tutorial/meshes/l_finger.dae"/>
        </geometry>
      </visual>
    </link>
  
    <joint name="left_tip_joint" type="fixed">
      <parent link="left_gripper"/>
      <child link="left_tip"/>
    </joint>
 
    <link name="left_tip">
      <visual>
        <origin rpy="0.0 0 0" xyz="0.09137 0.00495 0"/>
        <geometry>
# alternatives=package://pr2_description/meshes/gripper_v0/l_finger.dae 
     <mesh filename="package://urdf_tutorial/meshes/l_finger_tip.dae"/>
        </geometry>
      </visual>
    </link>
    <joint name="right_gripper_joint" type="fixed">
      <origin rpy="0 0 0" xyz="0.2 -0.01 0"/>
      <parent link="gripper_pole"/>
      <child link="right_gripper"/>
    </joint>
  
    <link name="right_gripper">
      <visual>
        <origin rpy="-3.1415 0 0" xyz="0 0 0"/>
        <geometry>
         <mesh filename="package://urdf_tutorial/meshes/l_finger.dae"/>
        </geometry>
      </visual>
    </link>
  
    <joint name="right_tip_joint" type="fixed">
      <parent link="right_gripper"/>
      <child link="right_tip"/>
    </joint>
 
    <link name="right_tip">
      <visual>
       <origin rpy="-3.1415 0 0" xyz="0.09137 0.00495 0"/>
        <geometry>
     <mesh filename="package://urdf_tutorial/meshes/l_finger_tip.dae"/>
        </geometry>
      </visual>
    </link>
  
   <link name="head">
      <visual>
        <geometry>
          <sphere radius="0.2"/>
       </geometry>
        <material name="red"/>
      </visual>
    </link>
#continuous joint can roll in both directions forever. but we can specify it's rotation by given "axis xyz".
   <joint name="head_swivel" type="continuous">
     <parent link="base_link"/>
      <child link="head"/>
	<axis xyz="0 0 1"/>
      <origin xyz="0 0 0.3"/>
    </joint>
  
    <link name="box">
      <visual>
        <geometry>
          <box size="0.08 0.08 0.08"/>
       </geometry>
        <material name="green"/>
      </visual>
    </link>
  
   <joint name="tobox" type="fixed">
      <parent link="head"/>
      <child link="box"/>
      <origin xyz="0.1814 0 0.1414"/>
   </joint>

<link name="lense">
    <visual>
      <origin rpy="0 0 0" xyz="0 0 0"/>
      <geometry>
        <cylinder length="0.1" radius="0.035"/>
      </geometry>
      <material name="black"/>
    </visual>
</link>

<joint name="tolens" type="fixed">
	<parent link= "box"/>
	<child link= "lense"/>
	<origin rpy= "0 1.57 0" xyz="0.015 0 0"/>
</joint>

<link name="eye">

</link>

<joint name="Orient_t0_lense" type="fixed">
	<parent link= "lense"/>
	<child link= "eye"/>
	<origin rpy= "0 0 -1.57" xzy="0 0 0"/>
</joint>



</robot>


